Workbook
Name JR_PAGE_ANCHOR_0_1: 'Daftar Barang dan Jasa'!$A$1

Sheet Tabung
A1: 45176
A2: NO | B2: KODE BARANG | C2: NAMA BARANG | D2: HARGA TERENDAH EXCLUDE PPN | F2: HARGA TERENDAH INCLUDE PPN
C4: TABUNG | D4: TANGGERANG | E4: SURABAYA | F4: TANGGERANG | G4: SURABAYA
A5: 1 | B5: TD-00-YD-000-002-PTH | C5: Dewar 2L (Cryogenic Container) | D5: =F5/1.11 -> 2297297.3 | E5: =G5/1.11 -> 2387387.4 | F5: 2550000 | G5: 2650000 | H5: 2550000 | I5: 2650000
A6: 2 | B6: TD-00-YD-000-003-PTH | C6: Dewar 3L (Cryogenic Container) | D6: =F6/1.11 -> 2342342.3 | E6: =G6/1.11 -> 2432432.4 | F6: 2600000 | G6: 2700000 | H6: 2600000 | I6: 2700000
A7: 3 | B7: TD-00-YD-000-006-PTH | C7: Dewar 6L (Cryogenic Container) | D7: =F7/1.11 -> 2342342.3 | E7: =G7/1.11 -> 2432432.4 | F7: 2600000 | G7: 2700000
A8: 4 | B8: TD-00-YD-000-010-PTH | C8: Dewar 10L (Cryogenic Container) | D8: =F8/1.11 -> 2432432.4 | E8: =G8/1.11 -> 2522522.5 | F8: 2700000 | G8: 2800000
A9: 5 | B9: TD-00-YD-000-020-PTH | C9: Dewar 20L (Cryogenic Container) | D9: =F9/1.11 -> 4054054.1 | E9: =G9/1.11 -> 4189189.2 | F9: 4500000 | G9: 4650000 | H9: 4500000 | I9: 4650000
A10: 6 | B10: TD-00-YD-000-030-PTH | C10: Dewar 30L (Cryogenic Container) | D10: =F10/1.11 -> 4684684.7 | E10: =G10/1.11 -> 4819819.8 | F10: 5200000 | G10: 5350000 | H10: 5200000 | I10: 5350000
A11: 7 | B11: TD-00-YD-000-035-PTH | C11: Dewar 35L (Cryogenic Container) | D11: =F11/1.11 -> 5225225.2 | E11: =G11/1.11 -> 5360360.4 | F11: 5800000 | G11: 5950000 | H11: 5800000 | I11: 5950000
A12: 8 | B12: TD-00-YD-000-050-PTH | C12: Dewar 50L (Cryogenic Container) | D12: =F12/1.11 -> 8648648.6 | E12: =G12/1.11 -> 8738738.7 | F12: 9600000 | G12: 9700000 | H12: 10000000 | I12: 10250000
A13: 9 | B13: AK-00-00-NCN-000-000 | C13: Nasal Canula | D13: =F13/1.11 -> 18018.018 | E13: =G13/1.11 -> 18018.018 | F13: 20000 | G13: 20000
A14: 10 | B14: AS-00-00-VPO-004-000 | C14: Optional Vaporizer Gas Outlet 4 pcs | D14: =F14/1.11 -> 1981982 | E14: =G14/1.11 -> 1981982 | F14: 2200000 | G14: 2200000
A15: 11 | B15: AS-00-00-VPI-003-000 | C15: Optional Vaporizer Liquid Inlet 3 pcs | D15: =F15/1.11 -> 2972973 | E15: =G15/1.11 -> 2972973 | F15: 3300000 | G15: 3300000
A16: 12 | B16: TB-00-PA-2GS-003-PTH | C16: Tabung 0,3 m3 PUREAIR QF-2G1 SV (kosong/isi O2) | D16: =F16/1.11 -> 265765.77 | E16: =G16/1.11 -> 265765.77 | F16: 295000 | G16: 295000 | H16: 295000 | I16: 295000
B17: TR-01-TB-2GS-O20-000/TR-03-TB-2GS-O20-000 | C17: Tabung Gas Baru Vol.0,3 M3 PA Putih QF -2G1 SV O2 GP | D17: =F17/1.11 -> 265765.77 | E17: =G17/1.11 -> 265765.77 | F17: 295000 | G17: 295000
A18: 13 | B18: TB-00-PA-2GS-005-PTH | C18: Tabung 0,5 m3 PUREAIR QF-2G1 SV (kosong/isi O2) | D18: =F18/1.11 -> 265765.77 | E18: =G18/1.11 -> 265765.77 | F18: 295000 | G18: 295000
B19: TR-01-TB-2GS-005-O20 | C19: Tabung 0,5 m3 QF-2G1 (kosong/isi O2) | D19: =F19/1.11 -> 265765.77 | E19: =G19/1.11 -> 265765.77 | F19: 295000 | G19: 295000
A20: 14 | B20: TR-01-TB-2G1-005-O20 | C20: Tabung Gas Baru Vol.0,5 M3 PA PutIh QF 2G1 O2 GP | D20: =F20/1.11 -> 265765.77 | E20: =G20/1.11 -> 265765.77 | F20: 295000 | G20: 295000
A21: 15 | B21: TR-01-TB-2G1-010-O20 | C21: Tabung 1 m3 PUREAIR QF-2G1 (kosong/isi O2) | D21: =F21/1.11 -> 265765.77 | E21: =G21/1.11 -> 265765.77 | F21: 295000 | G21: 295000
A22: 16 | B22: TB-00-PA-2GS-010-PTH | C22: Tabung 1 m3 PUREAIR QF-2G1 SV (kosong/isi O2) | D22: =F22/1.11 -> 265765.77 | E22: =G22/1.11 -> 265765.77 | F22: 295000 | G22: 295000
B23: TR-01-TB-2GS-010-O20/TR-03-TB-2GS-010-O20 | C23: Tabung Gas Baru Vol.1 M3 PA Putih QF-2G1 SV O2 GP | D23: =F23/1.11 -> 265765.77 | E23: =G23/1.11 -> 265765.77 | F23: 295000 | G23: 295000
A24: 17 | B24: TB-00-PA-2GS-015-PTH | C24: Tabung 1,5 m3 PUREAIR QF-2G1 SV (kosong/isi O2) | D24: =F24/1.11 -> 450450.45 | E24: =G24/1.11 -> 450450.45 | F24: 500000 | G24: 500000
B25: TR-01-TB-2GS-015-O20 | C25: Tabung Gas Baru Vol.1,5 M3 PA Putih QF-2G1 SV O2 GP | D25: =F25/1.11 -> 450450.45 | E25: =G25/1.11 -> 450450.45 | F25: 500000 | G25: 500000
A26: 18 | B26: TR-00-TB-2G1-15P-KS0 | C26: Tabung 1,5 m3 QF-2G1 (kosong/isi O2) | D26: =F26/1.11 -> 450450.45 | E26: =G26/1.11 -> 450450.45 | F26: 500000 | G26: 500000 | H26: Produk Samator
A27: 19 | B27: TB-00-UC-000-100-PTH | C27: Tabung 10 m3 (50L-200Bar) tanpa kran | D27: =F27/1.11 -> 1981982 | E27: =G27/1.11 -> 1981982 | F27: 2200000 | G27: 2200000
A28: 20 | B28: TB-00-UC-681-100-BRU | C28: Tabung 10 m3 (68L-150Bar) tanpa kran | D28: =F28/1.11 -> 2477477.5 | E28: =G28/1.11 -> 2477477.5 | F28: 2750000 | G28: 2750000
A29: 21 | B29: TR-00-TB-F6B-100-KS0 | C29: Tabung 10 m3 (50L-200Bar) kran QF-6B | D29: =F29/1.11 -> 2027027 | E29: =G29/1.11 -> 2027027 | F29: 2250000 | G29: 2250000
A30: 22 | B30: TR-00-TB-FT1-UC5-000 | C30: Tabung 10 m3 (50L-200Bar) kran QF-T1 | D30: =F30/1.11 -> 2072072.1 | E30: =G30/1.11 -> 2072072.1 | F30: 2300000 | G30: 2300000
A31: 23 | B31: TB-00-PA-2GS-020-PTH | C31: Tabung 2 m3 PUREAIR QF-2G1 SV (kosong/isi O2) | D31: =F31/1.11 -> 495495.5 | E31: =G31/1.11 -> 495495.5 | F31: 550000 | G31: 550000
B32: TR-01-TB-2GS-PP2-O20/TR-03-TB-2GS-PP2-O20 | C32: Tabung Gas Baru Vol.2 M3 PA Putih QF-2G1 SV O2 GP | D32: =F32/1.11 -> 495495.5 | E32: =G32/1.11 -> 495495.5 | F32: 550000 | G32: 550000
A33: 24 | B33: TB-00-PA-2GS-030-PTH | C33: Tabung 3 m3 pendek PUREAIR QF-2G1 SV (kosong/isi O2) | D33: =F33/1.11 -> 1081081.1 | E33: =G33/1.11 -> 1081081.1 | F33: 1200000 | G33: 1200000
B34: TR-01-TB-2GS-000-O20/TR-03-TB-2GS-000-O20 | C34: Tabung Gas Baru Vol.3 M3 - Putih QF-2G1 SV O2 GP | D34: =F34/1.11 -> 1081081.1 | E34: =G34/1.11 -> 1081081.1 | F34: 1200000 | G34: 1200000
A35: 25 | B35: TB-00-JP-2G1-060-BRU | C35: Tabung 6 m3 JP QF-2G1 kosong | D35: =F35/1.11 -> 900900.9 | E35: =G35/1.11 -> 923423.42 | F35: 1000000 | G35: 1025000
A36: 26 | B36: TR-00-TB-2G1-60B-KS0 | C36: Tabung 6 m3 PURE AIR QF-2G1 kosong | D36: =F36/1.11 -> 810810.81 | E36: =G36/1.11 -> 810810.81 | F36: 900000 | G36: 900000 | H36: 1000000 | I36: 1000000
A37: 27 | B37: TR-00-TB-2GS-60B-KS0 | C37: Tabung 6 m3 PURE AIR QF-2G1 SV kosong | D37: =F37/1.11 -> 810810.81 | E37: =G37/1.11 -> 810810.81 | F37: 900000 | G37: 900000
A38: 28 | B38: TB-00-YA-2G1-060-BRU | C38: Tabung 6 m3 YA QF-2G1 kosong | D38: =F38/1.11 -> 1261261.3 | E38: =G38/1.11 -> 1261261.3 | F38: 1400000 | G38: 1400000
A39: 29 | B39: TB-00-YA-2G1-060-BRU | C39: Tabung Gas Baru Vol.6 M3 UC - Putih QF-2G1 Tanpa Tutup KS | D39: =F39/1.11 -> 0 | E39: =G39/1.11 -> 0
B40: TB-00-YA-2G1-060-PTH | C40: Tabung Gas Baru Vol.6 M3 YA Putih QF-2G1 | D40: =F40/1.11 -> 0 | E40: =G40/1.11 -> 0
A41: 30 | B41: TB-00-JP-2G1-070-BRU | C41: Tabung 7 m3 PURE AIR QF-2G1 kosong (Indent 1,5 Bulan) | D41: =F41/1.11 -> 1126126.1 | E41: =G41/1.11 -> 1126126.1 | F41: 1250000 | G41: 1250000
...

Sheet Gas
A1: 45176
A2: NO | B2: KODE BARANG | C2: NAMA BARANG | D2: HARGA TERENDAH INCLUDE PPN
A4: GAS | D4: TANGGERANG | E4: SURABAYA
A5: 1 | B5: GS-00-00-ACT-001-000 | C5: Acetone 1 Kg | D5: 40000 | E5: 37500
A6: 2 | B6: GS-05-MR-ACY-2KG-WG0 | C6: Gas Acetylene WG (2 kg) | D6: 225000 | E6: 370000
A7: 3 | B7: GS-00-00-ACY-002-WG0 | C7: Gas Acetylene WG (3 kg) | D7: 340000 | E7: 370000
A8: 4 | B8: #N/A | C8: Gas Acetylene WG (4 kg) | D8: 450000 | E8: 0
A9: 5 | B9: #N/A | C9: Gas Acetylene WG (5 kg) | D9: 565000 | E9: 0
A10: 6 | B10: #N/A | C10: Gas Acetylene WG (6 kg) | D10: 675000 | E10: 0
A11: 7 | B11: GS-00-00-ACY-020-HP0 | C11: Gas Acetylene HP 2 kg | D11: 550000 | E11: 550000
A12: 8 | B12: GS-00-00-ACY-030-HP0 | C12: Gas Acetylene HP 3 Kg | D12: 775000 | E12: 775000
A13: 9 | B13: GS-00-00-ACY-040-HP0 | C13: Gas Acetylene HP 4 Kg | D13: 1000000 | E13: 1000000
A14: 10 | B14: GS-00-00-ACY-020-UHP | C14: Gas Acetylene UHP 2 kg | D14: 600000 | E14: 600000
A15: 11 | B15: GS-00-00-ACY-030-UHP | C15: Gas Acetylene UHP 3 Kg | D15: 850000 | E15: 850000
A16: 12 | B16: #N/A | C16: Gas Acetylene UHP 4 Kg | D16: 1100000 | E16: 1100000
A17: 13 | B17: GS-00-00-ACY-060-UHP | C17: Gas Acetylene UHP 6 Kg | D17: 1600000 | E17: 1600000
A18: 14 | B18: GS-00-00-ACY-040-WG0 | C18: Gas Acetylene WG (2 kg) + Acetone 4Kg | D18: 385000 | E18: 520000
A19: 15 | B19: GS-00-00-ACY-020-WG0 | C19: Gas Acetylene WG (2 kg)+ Aceton 5 Kg | D19: 425000 | E19: 557500
A20: 16 | B20: GS-00-00-ACY-030-WG0 | C20: Gas Acetylene WG (3 kg) + Aceton 6 Kg | D20: 580000 | E20: 595000
A21: 17 | B21: GS-00-00-AR0-003-WG0 | C21: Gas Argon 0,3 m3 WG | D21: 65000 | E21: 65000
A22: 18 | B22: GS-00-00-AR0-003-HP0 | C22: Gas Argon 0,3 m3 HP | D22: 165000 | E22: 165000
A23: 19 | B23: GS-00-00-AR0-003-UHP | C23: Gas Argon 0,3 m3 UHP | D23: 515000 | E23: 515000
A24: 20 | B24: GS-00-00-AR0-005-WG0 | C24: Gas Argon 0,5 m3 WG | D24: 65000 | E24: 75000
A25: 21 | B25: GS-00-00-AR0-005-HP0 | C25: Gas Argon 0,5 m3 HP | D25: 65000 | E25: 65000
A26: 22 | B26: GS-00-00-AR0-005-UHP | C26: Gas Argon 0,5 m3 UHP | D26: 515000 | E26: 500000
A27: 23 | B27: GS-00-00-AR0-010-WG0 | C27: Gas Argon 1 m3 WG | D27: 65000 | E27: 90000
A28: 24 | B28: GS-00-00-AR0-010-HP0 | C28: Gas Argon 1 m3 HP | D28: 165000 | E28: 150000
... A34: 30 | B34: GS-00-00-AR0-020-HP0 | C34: Gas Argon 2 m3 HP | D34: 165000 | E34: 165000
A35: 31 | B35: GS-00-00-AR0-020-UHP | C35: Gas Argon 2 m3 UHP | D35: 515000 | E35: 500000 | F35: 975000
A36: 32 | B36: GS-00-00-AR0-030-WG0 | C36: Gas Argon 3 m3 WG | D36: 140000 | E36: 150000 | F36: 975000
A37: 33 | B37: GS-00-00-AR0-060-WG0 | C37: Gas Argon 6 m3 WG | D37: 140000 | E37: 170000
A38: 34 | B38: GS-00-00-AR0-070-WG0 | C38: Gas Argon 7 m3 WG | D38: 165000 | E38: 195000
A39: 35 | B39: #N/A | C39: Gas Argon 6 m3 dan 7 m3 HP | D39: 245000 | E39: 245000
A40: 36 | B40: #N/A | C40: Gas Argon 6 m3 UHP | D40: 410000 | E40: 410000
A41: 36 | B41: #N/A | C41: Gas Argon 7 m3 UHP | D41: 470000 | E41: 470000
A42: 36 | B42: #N/A | C42: Gas Argon 8 m3 UHP | D42: 530000
A43: 37 | B43: #N/A | C43: Gas Argon 10 m3 - 200 Bar HP | D43: 850000
A44: 38 | B44: #N/A | C44: Gas Argon 10 m3 UHP (50L-200Bar) | D44: 1650000
A45: 39 | B45: GS-00-00-CO2-009-000 | C45: Gas Carbondioxide 9 kg | D45: 100000 | E45: 100000
A46: 40 | B46: GS-00-00-CO2-030-000 | C46: Gas Carbondioxide 30 Kg | D46: 270000 | E46: 165000
...

Sheet Liquid
A1: 45176
A2: NO | B2: KODE BARANG | C2: NAMA BARANG | D2: HARGA TERENDAH EXCLUDE PPN | F2: HARGA TERENDAH INCLUDE PPN
C4: LIQUID | D4: TANGGERANG | E4: SURABAYA | F4: TANGGERANG | G4: SURABAYA | I4: Liquid Argon 175L VGL
A5: 1 | B5: LQ-00-LA-175-VGL-000 | C5: Liquid Argon 175L VGL | D5: =F5/1.11 -> 3468468.5 | E5: =G5/1.11 -> 3468468.5 | F5: 3850000 | G5: 3850000 | I5: Liquid Carbondioxide Food Grade 210L
A6: 2 | B6: LQ-00-LC-175-000-000 | C6: Liquid Carbondioxide 175L | D6: =F6/1.11 -> 0 | E6: =G6/1.11 -> 1081081.1 | G6: 1200000 | I6: Liquid Level VGL 175 L m 18x2 LIN
A7: 3 | B7: LQ-00-LC-210-VGL-200 | C7: Liquid Carbondioxide 210L VGL (200Kg) | D7: =F7/1.11 -> 1576576.6 | E7: =G7/1.11 -> 1576576.6 | F7: 1750000 | G7: 1750000 | I7: Liquid Level VGL 175 L m 18x2 LOX
A8: 4 | B8: LQ-00-LN-001-000-000 | C8: Liquid Nitrogen | D8: =F8/1.11 -> 18018.018 | E8: =G8/1.11 -> 18018.018 | F8: 20000 | G8: 20000 | I8: Liquid Level VGL 175 L m 20x1,5 LAR
A9: 5 | B9: LQ-00-LN-003-000-000 | C9: Liquid Nitrogen 3L Dewar | D9: =F9/1.11 -> 112612.61 | E9: =G9/1.11 -> 112612.61 | F9: 125000 | G9: 125000 | I9: Liquid Nitrogen 175L VGL
A10: 6 | B10: LQ-00-LN-006-000-000 | C10: Liquid Nitrogen 6L Dewar | D10: =F10/1.11 -> 135135.14 | E10: =G10/1.11 -> 135135.14 | F10: 150000 | G10: 150000 | I10: Liquid Nitrogen 30L
A11: 7 | B11: LQ-00-LN-010-000-000 | C11: Liquid Nitrogen 10L Dewar | D11: =F11/1.11 -> 216216.22 | E11: =G11/1.11 -> 216216.22 | F11: 240000 | G11: 240000 | I11: Liquid Level VGL 175 L m 20x1,5 LCO2
A12: 8 | B12: LQ-00-LN-020-000-000 | C12: Liquid Nitrogen 20L Dewar | D12: =F12/1.11 -> 292792.79 | E12: =G12/1.11 -> 292792.79 | F12: 325000 | G12: 325000 | I12: Liquid Level VGL 175 L m 20x1,5 LNG
A13: 9 | B13: LQ-00-LN-030-000-000 | C13: Liquid Nitrogen 30L Dewar | D13: =F13/1.11 -> 373873.87 | E13: =G13/1.11 -> 373873.87 | F13: 415000 | G13: 415000 | I13: Liquid Nitrogen 1 Liter
A14: 10 | B14: LQ-00-LN-030-000-000 | C14: Liquid Nitrogen 35L Dewar | D14: =F14/1.11 -> 412162.16 | E14: =G14/1.11 -> 412162.16 | F14: 457500 | G14: 457500 | I14: Liquid Nitrogen 1 Liter
A15: 11 | B15: LQ-00-LN-050-000-000 | C15: Liquid Nitrogen 50L Dewar | D15: =F15/1.11 -> 531531.53 | E15: =G15/1.11 -> 531531.53 | F15: 590000 | G15: 590000 | I15: Liquid Nitrogen 20L
A16: 12 | B16: LQ-00-LN-175-VGL-000 | C16: Liquid Nitrogen 175L VGL | D16: =F16/1.11 -> 594594.59 | E16: =G16/1.11 -> 594594.59 | F16: 660000 | G16: 660000 | I16: Liquid Level VGL 175 L m 20x1,5 LIN
A17: 13 | B17: LQ-00-LN-210-VGL-000 | C17: Liquid Nitrogen 210L VGL | D17: =F17/1.11 -> 713513.51 | E17: =G17/1.11 -> 713513.51 | F17: 792000 | G17: 792000 | I17: Liquid Level VGL 175 L m 20x1,5 LOX
A18: 14 | B18: LQ-00-LN-360-000-000 | C18: Liquid Nitrogen 360L | D18: =F18/1.11 -> 1189189.2 | E18: =G18/1.11 -> 1189189.2 | F18: 1320000 | G18: 1320000 | I18: Liquid Nitrogen 10L
... A21: 17 | B21: LQ-00-LO-360-VGL-000 | C21: Liquid Oxygen 360L VGL | D21: =F21/1.11 -> 1351351.4 | E21: =G21/1.11 -> 1351351.4 | F21: 1500000 | G21: 1500000 | I21: Liquid Nitrogen 50L
I22: Liquid Nitrogen 6L
I24: Liquid Oxygen 175L
I25: Liquid Oxygen 360L
F63: 115000000 | G63: 115000000

Sheet Nama Barang
A1: Nama Barang | B1: Kode | C1: Unit | D1: Harga Baru | E1: Harga Min
E2: Tangerang | F2: Surabaya
A3: Aceton 4kg | B3: GS-00-00-ACT-040-000 | C3: TBG
A4: Aceton 4kg GRMP | B4: GS-01-00-ACT-040-000 | C4: TBG
A5: Aceton 4kg GRMR | B5: GS-02-00-ACT-040-000 | C5: TBG
A6: Aceton 6 Kg | B6: GS-00-00-ACT-060-000 | C6: TBG
A7: Aceton 6 Kg GRMP | B7: GS-01-00-ACT-060-000 | C7: TBG
A8: Aceton 6 Kg GRMR | B8: GS-02-00-ACT-060-000 | C8: TBG
A9: Acetone (1 Kg) | B9: GS-00-00-ACT-001-000 | C9: TBG
A10: Acetone (1 Kg) GRMP | B10: GS-01-00-ACT-001-000 | C10: TBG
A11: Acetone (1 Kg) GRMR | B11: GS-02-00-ACT-001-000 | C11: TBG
A12: Ambient Air Vaporizer 100 M3 - 35 Bar | B12: AS-00-UN-AVP-100-035 | C12: TBG
A13: Ambient Air Vaporizer 200 M3-35 Bar | B13: AS-00-UN-AVP-200-035 | C13: TBG
A14: Ambient Air Vaporizer 30 M3 - 35 Bar | B14: AS-00-UN-AVP-030-035 | C14: TBG
... A962: Vacum VGL 175L | B962: SS-00-000-000-063 | C962: TBG
C963: TBG
C964: TBG
C965: TBG
C966: TBG
C967: TBG
C968: TBG
C969: TBG
C970: TBG
C971: TBG
C972: TBG
C973: TBG
C974: TBG
... C1010: TBG

Sheet Kran
A1: 45176
A2: NO | B2: KODE BARANG | C2: NAMA BARANG | D2: HARGA TERENDAH EXCLUDE PPN | F2: HARGA TERENDAH INCLUDE PPN
C4: Kran | D4: TANGGERANG | E4: SURABAYA | F4: TANGGERANG | G4: SURABAYA
A5: 1 | B5: SP-00-00-APT-000-OCR | C5: As Pen Kran Acetylene CR | D5: =F5/1.11 -> 18018.018 | E5: =G5/1.11 -> 18018.018 | F5: 20000 | G5: 20000
A6: 2 | B6: SP-00-00-APC-000-ACY | C6: Aspen Monel Acy | D6: =F6/1.11 -> 22522.523 | E6: =G6/1.11 -> 27027.027 | F6: 25000 | G6: 30000
A7: 3 | B7: SP-00-00-APS-000-000 | C7: As Pen Sok | F7: 15000 | G7: 15000
A8: 4 | B8: SP-00-00-APS-000-000 | C8: As Pen PBB | F8: 20000 | G8: 20000
A9: 5 | B9: SP-00-00-BSN-HTM-000 | C9: Bunit Sok Nilon Hitam | F9: 15000 | G9: 15000
A10: 6 | B10: #N/A | C10: Biaya Cat Tabung | D10: =F10/1.11 -> 45045.045 | E10: =G10/1.11 -> 45045.045 | F10: 50000 | G10: 50000
A11: 7 | B11: #N/A | C11: Biaya Cat Tutup | D11: =F11/1.11 -> 4504.5045 | E11: =G11/1.11 -> 4504.5045 | F11: 5000 | G11: 5000
A12: 8 | B12: AS-00-00-CRD-175-120 | C12: Cradle Tabung VGL 175L-120L | D12: =F12/1.11 -> 1351351.4 | E12: =G12/1.11 -> 1486486.5 | F12: 1500000 | G12: 1650000
A13: 9 | C13: Cradle Tabung VGL 175L-210L | F13: 2000000 | G13: 2000000
A14: 10 | C14: Cradle Tabung/rack 16 tanpa manifold | F14: 13000000 | G14: 13000000
A15: 11 | C15: Cradle Tabung/rack 16 dengan manifold | F15: 25000000 | G15: 25000000
A16: 12 | B16: SP-00-000-CRP-000-000 | C16: Cryogenic Pump 300L-600L/h | D16: =F16/1.11 -> 1e+08 | E16: =G16/1.11 -> 1e+08 | F16: 111000000 | G16: 111000000
A17: 13 | B17: SP-00-00-CHP-000-000 | C17: Cryogenic Hand Pump | D17: =F17/1.11 -> 2252252.3 | E17: =G17/1.11 -> 2252252.3 | F17: 2500000 | G17: 2500000
A18: 14 | B18: TR-00-TV-VGL-175-023 | C18: Cryogenic Meter 175L | D18: =F18/1.11 -> 644144.14 | E18: =G18/1.11 -> 644144.14 | F18: 715000 | G18: 715000
A19: 15 | B19: SP-00-00-CPG-PSI-NPT | C19: Cryogenic Pressure Gauge 600psi NPT 1/4 | D19: =F19/1.11 -> 202702.7 | E19: =G19/1.11 -> 202702.7 | F19: 225000 | G19: 225000
A20: 16 | B20: SP-00-000-CPP-000-005 | C20: Cryogenic Pump Part P200-005 | D20: =F20/1.11 -> 0 | E20: =G20/1.11 -> 0
A21: 17 | B21: SP-00-000-CPP-000-006 | C21: Cryogenic Pump Part P200-006 | D21: =F21/1.11 -> 0 | E21: =G21/1.11 -> 0
A22: 18 | B22: SP-00-000-CPP-000-007 | C22: Cryogenic Pump Part P200-007 | D22: =F22/1.11 -> 0 | E22: =G22/1.11 -> 0
A23: 19 | B23: SP-00-00-CVR-000-000 | C23: Cryogenic Valve Repair Kit | D23: =F23/1.11 -> 198198.2 | E23: =G23/1.11 -> 198198.2 | F23: 220000 | G23: 220000 | H23: Cryogenic Container
A24: 20 | B24: SP-00-00-HKR-000-000 | C24: Handwheel Kran | D24: =F24/1.11 -> 7207.2072 | E24: =G24/1.11 -> 7207.2072 | F24: 8000 | G24: 8000
A25: 21 | B25: SP-00-00-HKR-000-KSV | C25: Handwheel Kran SV | D25: =F25/1.11 -> 11711.712 | E25: =G25/1.11 -> 11711.712 | F25: 13000 | G25: 13000
A26: 22 | C26: Mur Handwheel | D26: =F26/1.11 -> 2252.2523 | F26: 2500 | G26: 2500
A27: 23 | C27: Per Handwheel | F27: 2500 | G27: 2500
A28: 24 | B28: SP-00-00-KRT-000-ORI | C28: Kran Acetylene Baru Type PF5-1 | D28: =F28/1.11 -> 144144.14 | E28: =G28/1.11 -> 144144.14 | F28: 160000 | G28: 160000
A29: 25 | B29: #N/A | C29: Kran Argon BaruType PX-35 SA | D29: =F29/1.11 -> 198198.2 | E29: =G29/1.11 -> 198198.2 | F29: 220000 | G29: 220000
A30: 26 | B30: SP-00-UN-KRK-2A6-ORI | C30: Kran Carbondioxide QF-2A6 | D30: =F30/1.11 -> 83333.333 | E30: =G30/1.11 -> 83333.333 | F30: 92500 | G30: 92500
A31: 27 | B31: SP-00-UN-KRK-2A6-KLP | C31: Kran Carbondioxide QF-2A6 Lepasan | D31: =F31/1.11 -> 78828.829 | E31: =G31/1.11 -> 78828.829 | F31: 87500 | G31: 87500
A32: 28 | B32: SP-00-UN-KRK-000-KSV | C32: Kran Carbondioxide QF-2A6 SV | D32: =F32/1.11 -> 83333.333 | E32: =G32/1.11 -> 83333.333 | F32: 92500 | G32: 92500
A33: 29 | B33: SP-00-UN-KRK-000-KSV | C33: Kran Carbondioxide QF-2A6 SV Lepasan | D33: =F33/1.11 -> 78828.829 | E33: =G33/1.11 -> 78828.829 | F33: 87500 | G33: 87500
A34: 30 | B34: SP-00-UN-KRH-F30-ORI | C34: Kran Hidrogen QF-30 | D34: =F34/1.11 -> 130630.63 | E34: =G34/1.11 -> 130630.63 | F34: 145000 | G34: 145000
A35: 31 | B35: SP-00-DN-KRH-000-000 | C35: Kran Hydrogen Baru Type DN | D35: =F35/1.11 -> 270270.27 | E35: =G35/1.11 -> 0 | F35: 300000
A36: 32 | B36: SP-00-00-KRK-000-CO0 | C36: Kran Karbonmonoksida Baru | D36: =F36/1.11 -> 85585.586 | E36: =G36/1.11 -> 0 | F36: 95000
A37: 33 | B37: SP-00-00-KRC-FT1-CNG | C37: Kran Natural Gas QF-T1 (CNG) | D37: =F37/1.11 -> 198198.2 | E37: =G37/1.11 -> 198198.2 | F37: 220000 | G37: 220000
A38: 34 | B38: SP-00-00-KNO-000-000 | C38: Kran Nitrous Oxide | D38: =F38/1.11 -> 315315.32 | E38: =G38/1.11 -> 315315.32 | F38: 350000 | G38: 350000
A39: 35 | B39: SP-00-UN-KRO-2G1-ORI | C39: Kran Oksigen QF-2G1 | D39: =F39/1.11 -> 83333.333 | E39: =G39/1.11 -> 83333.333 | F39: 92500 | G39: 92500
A40: 36 | B40: #N/A | C40: Kran Oksigen QF-2G1 Chrome | D40: =F40/1.11 -> 83333.333 | E40: =G40/1.11 -> 83333.333 | F40: 92500 | G40: 92500
A41: 37 | B41: SP-00-UN-KRO-2G1-KLP | C41: Kran Oksigen QF-2G1 Lepasan | D41: =F41/1.11 -> 78828.829 | E41: =G41/1.11 -> 78828.829 | F41: 87500 | G41: 87500
...

Sheet Daftar Barang dan Jasa
D1: PT. Nisson Indonesia
D2: Daftar Barang dan Jasa
B4: Cabang : Tangerang, Surabaya, Filter berdasarkan : Kategori Barang
D5: Kode Barang | E5: Nama Barang | G5: Jenis Barang | H5: Daftar Harga
D6: Aksesoris | H6: Tangerang | I6: Surabaya
D7: AS-00-UN-AVP-030-035 | E7: Ambient Air Vaporizer 30 M3 - 35 Bar | G7: Persediaan | H7: =Tabung!F59 -> 6500000 | I7: =Tabung!G59 -> 7000000
D8: AS-00-UN-AVP-050-035 | E8: Ambient Air Vaporizer 50 M3 - 35 Bar | G8: Persediaan | H8: =Tabung!F60 -> 9700000 | I8: =Tabung!G60 -> 10200000
D9: AS-00-UN-AVP-100-035 | E9: Ambient Air Vaporizer 100 M3 - 35 Bar | G9: Persediaan | H9: =Tabung!F57 -> 17500000 | I9: =Tabung!G57 -> 18250000
D10: AS-00-00-MAN-006-000 | E10: Pengisian Manifold 6 titik | G10: Persediaan | H10: =Kran!F53 -> 7200000 | I10: =Kran!G53 -> 7500000
D11: AS-00-00-MAN-010-001 | E11: Pengisian Manifold 10 titik | G11: Persediaan | H11: =Kran!F51 -> 12000000 | I11: =Kran!G51 -> 12500000
D12: AS-00-00-MAN-006-TK0 | E12: Pengisian Manifold 6 titik tanpa kran | G12: Persediaan | H12: =Kran!F53+(Kran!F54*6) -> 6900000 | I12: =Kran!G53+(Kran!G54*6) -> 7200000
D13: AS-00-UN-TRL-010-000 | E13: Troli Union 1M3 | G13: Persediaan | H13: =Kran!F82 -> 100000 | I13: =Kran!G82 -> 100000
D14: AS-00-UN-TRL-015-000 | E14: Troli Union 1,5M3 | G14: Persediaan | H14: =Kran!F83 -> 125000 | I14: =Kran!G83 -> 125000
D15: AS-00-UN-TRL-020-000 | E15: Troli Union 2M3 | G15: Persediaan | H15: =Kran!F84 -> 125000 | I15: =Kran!G84 -> 125000
D16: AS-00-UN-TRL-060-000 | E16: Troli Union 6M3 | G16: Persediaan | H16: =Kran!F85 -> 750000 | I16: =Kran!G85 -> 750000
D17: AS-00-00-TRL-005-000 | E17: Troli Single 0.5 M3 | G17: Persediaan | H17: =Kran!F78 -> 55000 | I17: =Kran!G78 -> 65000
D18: AS-00-00-TRL-010-000 | E18: Troli Single 1 M3 | G18: Persediaan | H18: =Kran!F79 -> 55000 | I18: =Kran!G79 -> 65000
D19: AS-00-00-TRL-020-000 | E19: Troli Single 2 M3 | G19: Persediaan | H19: =Kran!F80 -> 65000 | I19: =Kran!G80 -> 75000
D20: AS-00-00-TRL-060-000 | E20: Troli Single 6 M3 | G20: Persediaan | H20: =Kran!F81 -> 375000 | I20: =Kran!G81 -> 400000
D21: AS-00-00-TTB-000-000 | E21: Tutup Tulip Besi/Baja | G21: Persediaan | H21: =Kran!F88 -> 50000 | I21: =Kran!G88 -> 50000
D22: AS-00-00-TTP-000-000 | E22: Tutup Tulip Plastik | G22: Persediaan | H22: =Kran!F89 -> 50000 | I22: =Kran!G89 -> 50000
D23: AS-00-00-TCB-000-000 | E23: Tutup Tabung Baja Standar | G23: Persediaan | H23: =Kran!F87 -> 35000 | I23: =Kran!G87 -> 35000
D24: AS-00-00-TCP-000-000 | E24: Tutup Tabung Acetylene Plastik | G24: Persediaan | H24: =Kran!F86 -> 50000 | I24: =Kran!G86 -> 50000
D25: AS-00-00-VPI-003-000 | E25: Optional Vaporizer Liquid Inlet 3 PCS | G25: Persediaan | H25: =Tabung!F15 -> 3300000 | I25: =Tabung!G15 -> 3300000
D26: AS-00-00-VPO-004-000 | E26: Optional Vaporizer Liquid Outlet 4 PCS | G26: Persediaan | H26: =Tabung!F14 -> 2200000 | I26: =Tabung!G14 -> 2200000
D27: AS-00-00-MAN-005-000 | E27: Pengisian Manifold 5 titik | G27: Persediaan | H27: =Kran!F52 -> 6000000 | I27: =Kran!G52 -> 6250000
D28: AS-00-UN-AVP-200-035 | E28: Ambient Air Vaporizer 200 M3-35 Bar | G28: Persediaan | H28: =Tabung!F58 -> 35000000 | I28: =Tabung!G58 -> 36000000
D29: AK-00-BM-REO-000-000 | E29: Regulator Medis Oksigen BMD | G29: Persediaan | H29: =Kran!F72 -> 175000 | I29: =Kran!G72 -> 175000
D30: AK-00-NS-REO-000-000 | E30: Regulator Medis Oksigen Nesco | G30: Persediaan | H30: =Kran!F68 -> 140000 | I30: =Kran!G68 -> 140000
D31: AK-00-CM-REO-000-000 | E31: Regulator Medis Oksigen Cosmo Med | G31: Persediaan | H31: =Kran!F69 -> 140000 | I31: =Kran!G69 -> 140000
D32: AK-00-OM-REO-000-000 | E32: Regulator Medis Oksigen Onemed | G32: Persediaan | H32: =Kran!F70 -> 280000 | I32: =Kran!G70 -> 280000
D33: AK-00-AV-REO-000-000 | E33: Regulator Medis Oksigen Avico | G33: Persediaan | H33: =Kran!F66 -> 165000 | I33: =Kran!G66 -> 165000
D34: AK-00-WM-REO-000-000 | E34: Regulator Medis Oksigen Welding Morris | G34: Persediaan | H34: =Kran!F71 -> 550000 | I34: =Kran!G71 -> 550000
D35: AK-00-00-REA-000-000 | E35: Regulator Gas Acetylene NN | G35: Persediaan | H35: =Kran!F64 -> 125000 | I35: =Kran!G64 -> 125000
D36: AK-00-MS-REA-000-000 | E36: Regulator Gas Acetylene Morris | G36: Persediaan | H36: =Kran!F65 -> 550000 | I36: =Kran!G65 -> 550000
D37: AK-00-00-NCN-000-000 | E37: Nasal Canula | G37: Persediaan | H37: 20000 | I37: 20000
D38: GS-06-MR-UT0-070-000 | E38: Gas Udara Tekan 7m3 GP | G38: Persediaan | H38: =Gas!D142 -> 50000 | I38: =Gas!E142 -> 135000
D39: GS-06-MR-UT0-060-000 | E39: Gas Udara Tekan 6m3 GP | G39: Persediaan | H39: =Gas!D142 -> 50000 | I39: =Gas!E142 -> 135000
D40: GS-00-FG-CO2-000-025 | E40: Gas Carbondioxide 25 Kg FG | G40: Persediaan | H40: =Gas!D69 -> 168750 | I40: =Gas!E69 -> 162500
D41: GS-05-MR-O20-010-000 | E41: Gas Oksigen 1 M3 GPMP | G41: Persediaan | H41: =Gas!D129 -> 17000 | I41: =Gas!E129 -> 17000
...
